I'm sorry, but an uncaught exception occurred.

While running game code:
  File "game/script.rpy", line 48, in script
    n "My name is [povname]!"
KeyError: u'povname'

-- Full Traceback ------------------------------------------------------------

Full traceback:
  File "game/script.rpy", line 48, in script
    n "My name is [povname]!"
  File "E:\Programming Center\RenPy\renpy-6.99.13-sdk\renpy\ast.py", line 624, in execute
    renpy.exports.say(who, what, interact=self.interact, *args, **kwargs)
  File "E:\Programming Center\RenPy\renpy-6.99.13-sdk\renpy\exports.py", line 1173, in say
    who(what, *args, **kwargs)
  File "E:\Programming Center\RenPy\renpy-6.99.13-sdk\renpy\character.py", line 902, in __call__
    what = what_pattern.replace("[what]", sub(what, translate=translate))
  File "E:\Programming Center\RenPy\renpy-6.99.13-sdk\renpy\character.py", line 884, in sub
    return renpy.substitutions.substitute(s, scope=scope, force=force, translate=translate)[0]
  File "E:\Programming Center\RenPy\renpy-6.99.13-sdk\renpy\substitutions.py", line 242, in substitute
    s = formatter.vformat(s, (), kwargs)
  File "/home/tom/ab/x64lucid-deps/install/lib/python2.7/string.py", line 563, in vformat
  File "/home/tom/ab/x64lucid-deps/install/lib/python2.7/string.py", line 585, in _vformat
  File "/home/tom/ab/x64lucid-deps/install/lib/python2.7/string.py", line 646, in get_field
  File "/home/tom/ab/x64lucid-deps/install/lib/python2.7/string.py", line 605, in get_value
KeyError: u'povname'

Windows-8-6.2.9200
Ren'Py 6.99.13.2919
gameTestbed 1.0
